Workbook

Sheet 재고현황
A1: FactoryScribe 더미 데이터 - 재고현황 | B1: FactoryScribe 더미 데이터 - 재고현황 | C1: FactoryScribe 더미 데이터 - 재고현황 | D1: FactoryScribe 더미 데이터 - 재고현황 | E1: FactoryScribe 더미 데이터 - 재고현황 | F1: FactoryScribe 더미 데이터 - 재고현황 | G1: FactoryScribe 더미 데이터 - 재고현황 | H1: FactoryScribe 더미 데이터 - 재고현황 | I1: FactoryScribe 더미 데이터 - 재고현황 | J1: FactoryScribe 더미 데이터 - 재고현황 | K1: FactoryScribe 더미 데이터 - 재고현황 | L1: FactoryScribe 더미 데이터 - 재고현황 | M1: FactoryScribe 더미 데이터 - 재고현황 | N1: FactoryScribe 더미 데이터 - 재고현황 | R1: FactoryScribe 더미 데이터 - 재고현황 | S1: FactoryScribe 더미 데이터 - 재고현황 | T1: FactoryScribe 더미 데이터 - 재고현황 | U1: FactoryScribe 더미 데이터 - 재고현황
A2: 재고 잔여량, 부족 재고, 부품가격 상승률, 예상 소진일 계산 테스트용 데이터입니다. | B2: 재고 잔여량, 부족 재고, 부품가격 상승률, 예상 소진일 계산 테스트용 데이터입니다. | C2: 재고 잔여량, 부족 재고, 부품가격 상승률, 예상 소진일 계산 테스트용 데이터입니다. | D2: 재고 잔여량, 부족 재고, 부품가격 상승률, 예상 소진일 계산 테스트용 데이터입니다. | E2: 재고 잔여량, 부족 재고, 부품가격 상승률, 예상 소진일 계산 테스트용 데이터입니다. | F2: 재고 잔여량, 부족 재고, 부품가격 상승률, 예상 소진일 계산 테스트용 데이터입니다. | G2: 재고 잔여량, 부족 재고, 부품가격 상승률, 예상 소진일 계산 테스트용 데이터입니다. | H2: 재고 잔여량, 부족 재고, 부품가격 상승률, 예상 소진일 계산 테스트용 데이터입니다. | I2: 재고 잔여량, 부족 재고, 부품가격 상승률, 예상 소진일 계산 테스트용 데이터입니다. | J2: 재고 잔여량, 부족 재고, 부품가격 상승률, 예상 소진일 계산 테스트용 데이터입니다. | K2: 재고 잔여량, 부족 재고, 부품가격 상승률, 예상 소진일 계산 테스트용 데이터입니다. | L2: 재고 잔여량, 부족 재고, 부품가격 상승률, 예상 소진일 계산 테스트용 데이터입니다. | M2: 재고 잔여량, 부족 재고, 부품가격 상승률, 예상 소진일 계산 테스트용 데이터입니다. | N2: 재고 잔여량, 부족 재고, 부품가격 상승률, 예상 소진일 계산 테스트용 데이터입니다. | R2: 재고 잔여량, 부족 재고, 부품가격 상승률, 예상 소진일 계산 테스트용 데이터입니다. | S2: 재고 잔여량, 부족 재고, 부품가격 상승률, 예상 소진일 계산 테스트용 데이터입니다. | T2: 재고 잔여량, 부족 재고, 부품가격 상승률, 예상 소진일 계산 테스트용 데이터입니다. | U2: 재고 잔여량, 부족 재고, 부품가격 상승률, 예상 소진일 계산 테스트용 데이터입니다.
A4: 품목코드 | B4: 품목명 | C4: 카테고리 | D4: 규격 | E4: 단위 | F4: 공급사 | G4: 현재고 | H4: 안전재고 | I4: 적정재고 | J4: 평균월사용량 | K4: 현재단가 | L4: 전월단가 | M4: 가격상승률 | N4: 재고상태 | O4: 전년도 사용 수량 | P4: 현재 잔여 수량 | Q4: 이번년도 예상 수량 | R4: 예상소진일 | S4: 창고위치 | T4: 최종입고일 | U4: 비고
A5: FS-RM-001 | B5: 컨트롤 PCB | C5: 부자재 | D5: 고내열-11 | E5: ROLL | F5: 한빛전장 | G5: 153 | H5: 68 | I5: 121 | J5: 49 | K5: 73400 | L5: 65930 | M5: =IF(L5=0,0,(K5-L5)/L5) -> 0.11330199 | N5: =IF(G5<H5,"부족",IF(G5<H5*1.25,"주의","정상")) -> 정상 | O5: 34625 | P5: 21079 | Q5: 33548 | R5: =IF(J5=0,"",ROUND(G5/(J5/30),0)) -> 94 | S5: 1창고-A1 | T5: 46149
A6: FS-PK-002 | B6: 서보 모터 | C6: 부자재 | D6: A형-12 | E6: ROLL | F6: 대성정밀 | G6: 55 | H6: 70 | I6: 147 | J6: 106 | K6: 66150 | L6: 58590 | M6: =IF(L6=0,0,(K6-L6)/L6) -> 0.12903226 | N6: =IF(G6<H6,"부족",IF(G6<H6*1.25,"주의","정상")) -> 부족 | O6: 39726 | P6: 26484 | Q6: 28755 | R6: =IF(J6=0,"",ROUND(G6/(J6/30),0)) -> 16 | S6: 1창고-A2 | T6: 46143 | U6: 안전재고 미만
A7: FS-PN-003 | B7: 알루미늄 브라켓 | C7: 소모품 | D7: A형-13 | E7: M | F7: 베트남파트너스 | G7: 119 | H7: 76 | I7: 137 | J7: 75 | K7: 55190 | L7: 55340 | M7: =IF(L7=0,0,(K7-L7)/L7) -> -0.0027105168 | N7: =IF(G7<H7,"부족",IF(G7<H7*1.25,"주의","정상")) -> 정상 | O7: 39736 | P7: 25990 | Q7: 34217 | R7: =IF(J7=0,"",ROUND(G7/(J7/30),0)) -> 48 | S7: 2창고-B1 | T7: 46136
A8: FS-MC-004 | B8: M3 육각볼트 | C8: 포장재 | D8: A형-14 | E8: ROLL | F8: 유니텍소재 | G8: 21 | H8: 46 | I8: 79 | J8: 65 | K8: 7000 | L8: 6790 | M8: =IF(L8=0,0,(K8-L8)/L8) -> 0.030927835 | N8: =IF(G8<H8,"부족",IF(G8<H8*1.25,"주의","정상")) -> 부족 | O8: 37732 | P8: 21435 | Q8: 30686 | R8: =IF(J8=0,"",ROUND(G8/(J8/30),0)) -> 10 | S8: 2창고-B3 | T8: 46152 | U8: 안전재고 미만
A9: FS-MC-005 | B9: 리니어 가이드 | C9: 원자재 | D9: 방수-15 | E9: SET | F9: 동양패키징 | G9: 35 | H9: 48 | I9: 99 | J9: 45 | K9: 54530 | L9: 52760 | M9: =IF(L9=0,0,(K9-L9)/L9) -> 0.033548143 | N9: =IF(G9<H9,"부족",IF(G9<H9*1.25,"주의","정상")) -> 부족 | O9: 39769 | P9: 21989 | Q9: 26095 | R9: =IF(J9=0,"",ROUND(G9/(J9/30),0)) -> 23 | S9: 3창고-C2 | T9: 46165 | U9: 안전재고 미만
A10: FS-RM-006 | B10: 전원 케이블 | C10: 부자재 | D10: 고내열-16 | E10: ROLL | F10: 세명산업 | G10: 128 | H10: 62 | I10: 130 | J10: 60 | K10: 72470 | L10: 68630 | M10: =IF(L10=0,0,(K10-L10)/L10) -> 0.055952207 | N10: =IF(G10<H10,"부족",IF(G10<H10*1.25,"주의","정상")) -> 정상 | O10: 39670 | P10: 22009 | Q10: 32283 | R10: =IF(J10=0,"",ROUND(G10/(J10/30),0)) -> 64 | S10: 외주창고-VN | T10: 46171
A11: FS-PN-007 | B11: 스위칭 전원공급기 | C11: 부자재 | D11: A형-17 | E11: KG | F11: K-Parts | G11: 37 | H11: 27 | I11: 51 | J11: 44 | K11: 63830 | L11: 56190 | M11: =IF(L11=0,0,(K11-L11)/L11) -> 0.13596725 | N11: =IF(G11<H11,"부족",IF(G11<H11*1.25,"주의","정상")) -> 정상 | O11: 37216 | P11: 27749 | Q11: 29399 | R11: =IF(J11=0,"",ROUND(G11/(J11/30),0)) -> 25 | S11: 1창고-A1 | T11: 46194
A12: FS-RM-008 | B12: 근접센서 | C12: 부자재 | D12: 표준-18 | E12: ROLL | F12: 한빛전장 | G12: 13 | H12: 24 | I12: 60 | J12: 32 | K12: 19910 | L12: 17750 | M12: =IF(L12=0,0,(K12-L12)/L12) -> 0.12169014 | N12: =IF(G12<H12,"부족",IF(G12<H12*1.25,"주의","정상")) -> 부족 | O12: 36196 | P12: 28226 | Q12: 27347 | R12: =IF(J12=0,"",ROUND(G12/(J12/30),0)) -> 12 | S12: 1창고-A2 | T12: 46183 | U12: 안전재고 미만
A13: FS-EL-009 | B13: 실리콘 패킹 | C13: 부자재 | D13: 방수-19 | E13: BOX | F13: 대성정밀 | G13: 26 | H13: 17 | I13: 42 | J13: 11 | K13: 88470 | L13: 77540 | M13: =IF(L13=0,0,(K13-L13)/L13) -> 0.1409595 | N13: =IF(G13<H13,"부족",IF(G13<H13*1.25,"주의","정상")) -> 정상 | O13: 31261 | P13: 26659 | Q13: 23221 | R13: =IF(J13=0,"",ROUND(G13/(J13/30),0)) -> 71 | S13: 2창고-B1 | T13: 46186
A14: FS-PN-010 | B14: 박스 라벨 | C14: 소모품 | D14: 방수-20 | E14: M | F14: 베트남파트너스 | G14: 75 | H14: 32 | I14: 70 | J14: 38 | K14: 87610 | L14: 84690 | M14: =IF(L14=0,0,(K14-L14)/L14) -> 0.034478687 | N14: =IF(G14<H14,"부족",IF(G14<H14*1.25,"주의","정상")) -> 정상 | O14: 39219 | P14: 25226 | Q14: 26861 | R14: =IF(J14=0,"",ROUND(G14/(J14/30),0)) -> 59 | S14: 2창고-B3 | T14: 46165
A15: FS-PK-011 | B15: 포장 완충재 | C15: 포장재 | D15: A형-21 | E15: BOX | F15: 유니텍소재 | G15: 36 | H15: 46 | I15: 84 | J15: 45 | K15: 57670 | L15: 56950 | M15: =IF(L15=0,0,(K15-L15)/L15) -> 0.012642669 | N15: =IF(G15<H15,"부족",IF(G15<H15*1.25,"주의","정상")) -> 부족 | O15: 35977 | P15: 24136 | Q15: 31285 | R15: =IF(J15=0,"",ROUND(G15/(J15/30),0)) -> 24 | S15: 3창고-C2 | T15: 46181 | U15: 안전재고 미만
A16: FS-EL-012 | B16: 스테인리스 샤프트 | C16: 원자재 | D16: A형-22 | E16: EA | F16: 동양패키징 | G16: 179 | H16: 77 | I16: 183 | J16: 69 | K16: 19820 | L16: 19900 | M16: =IF(L16=0,0,(K16-L16)/L16) -> -0.0040201005 | N16: =IF(G16<H16,"부족",IF(G16<H16*1.25,"주의","정상")) -> 정상 | O16: 31125 | P16: 23556 | Q16: 30266 | R16: =IF(J16=0,"",ROUND(G16/(J16/30),0)) -> 78 | S16: 외주창고-VN | T16: 46150
A17: FS-EL-013 | B17: 공압 실린더 | C17: 부자재 | D17: 고내열-23 | E17: BOX | F17: 세명산업 | G17: 79 | H17: 35 | I17: 75 | J17: 38 | K17: 6490 | L17: 6410 | M17: =IF(L17=0,0,(K17-L17)/L17) -> 0.012480499 | N17: =IF(G17<H17,"부족",IF(G17<H17*1.25,"주의","정상")) -> 정상 | O17: 33519 | P17: 26545 | Q17: 23238 | R17: =IF(J17=0,"",ROUND(G17/(J17/30),0)) -> 62 | S17: 1창고-A1 | T17: 46136
A18: FS-EL-014 | B18: 솔레노이드 밸브 | C18: 부자재 | D18: B형-24 | E18: BOX | F18: K-Parts | G18: 58 | H18: 78 | I18: 183 | J18: 73 | K18: 45850 | L18: 46220 | M18: =IF(L18=0,0,(K18-L18)/L18) -> -0.0080051926 | N18: =IF(G18<H18,"부족",IF(G18<H18*1.25,"주의","정상")) -> 부족 | O18: 33562 | P18: 23391 | Q18: 31225 | R18: =IF(J18=0,"",ROUND(G18/(J18/30),0)) -> 24 | S18: 1창고-A2 | T18: 46163 | U18: 안전재고 미만
A19: FS-PK-015 | B19: 터미널 블록 | C19: 부자재 | D19: 고내열-25 | E19: BOX | F19: 한빛전장 | G19: 19 | H19: 27 | I19: 67 | J19: 21 | K19: 59780 | L19: 61150 | M19: =IF(L19=0,0,(K19-L19)/L19) -> -0.022403925 | N19: =IF(G19<H19,"부족",IF(G19<H19*1.25,"주의","정상")) -> 부족 | O19: 39707 | P19: 21682 | Q19: 30375 | R19: =IF(J19=0,"",ROUND(G19/(J19/30),0)) -> 27 | S19: 2창고-B1 | T19: 46128 | U19: 안전재고 미만
A20: FS-RM-016 | B20: 릴레이 모듈 | C20: 부자재 | D20: 표준-26 | E20: ROLL | F20: 대성정밀 | G20: 9 | H20: 22 | I20: 47 | J20: 27 | K20: 5960 | L20: 6080 | M20: =IF(L20=0,0,(K20-L20)/L20) -> -0.019736842 | N20: =IF(G20<H20,"부족",IF(G20<H20*1.25,"주의","정상")) -> 부족 | O20: 36104 | P20: 23439 | Q20: 31607 | R20: =IF(J20=0,"",ROUND(G20/(J20/30),0)) -> 10 | S20: 2창고-B3 | T20: 46142 | U20: 안전재고 미만
A21: FS-MC-017 | B21: ABS 하우징 | C21: 소모품 | D21: 고내열-27 | E21: M | F21: 베트남파트너스 | G21: 78 | H21: 32 | I21: 62 | J21: 47 | K21: 1790 | L21: 1600 | M21: =IF(L21=0,0,(K21-L21)/L21) -> 0.11875 | N21: =IF(G21<H21,"부족",IF(G21<H21*1.25,"주의","정상")) -> 정상 | O21: 35249 | P21: 28489 | Q21: 23177 | R21: =IF(J21=0,"",ROUND(G21/(J21/30),0)) -> 50 | S21: 3창고-C2 | T21: 46183
A22: FS-EL-018 | B22: 동 부스바 | C22: 포장재 | D22: A형-28 | E22: ROLL | F22: 유니텍소재 | G22: 192 | H22: 82 | I22: 154 | J22: 88 | K22: 38230 | L22: 34030 | M22: =IF(L22=0,0,(K22-L22)/L22) -> 0.12342051 | N22: =IF(G22<H22,"부족",IF(G22<H22*1.25,"주의","정상")) -> 정상 | O22: 32406 | P22: 20261 | Q22: 23845 | R22: =IF(J22=0,"",ROUND(G22/(J22/30),0)) -> 65 | S22: 외주창고-VN | T22: 46140
A23: FS-EL-019 | B23: 엔코더 케이블 | C23: 원자재 | D23: 방수-29 | E23: ROLL | F23: 동양패키징 | G23: 104 | H23: 58 | I23: 130 | J23: 41 | K23: 77320 | L23: 73870 | M23: =IF(L23=0,0,(K23-L23)/L23) -> 0.046703669 | N23: =IF(G23<H23,"부족",IF(G23<H23*1.25,"주의","정상")) -> 정상 | O23: 36590 | P23: 27575 | Q23: 32928 | R23: =IF(J23=0,"",ROUND(G23/(J23/30),0)) -> 76 | S23: 1창고-A1 | T23: 46154
A24: FS-MC-020 | B24: 열수축 튜브 | C24: 부자재 | D24: 고내열-30 | E24: BOX | F24: 세명산업 | G24: 47 | H24: 39 | I24: 98 | J24: 31 | K24: 19770 | L24: 18890 | M24: =IF(L24=0,0,(K24-L24)/L24) -> 0.046585495 | N24: =IF(G24<H24,"부족",IF(G24<H24*1.25,"주의","정상")) -> 주의 | O24: 30633 | P24: 26058 | Q24: 26208 | R24: =IF(J24=0,"",ROUND(G24/(J24/30),0)) -> 45 | S24: 1창고-A2 | T24: 46134 | U24: 재고 소진 임박
A25: FS-EL-021 | B25: 베어링 608ZZ | C25: 부자재 | D25: A형-31 | E25: M | F25: K-Parts | G25: 33 | H25: 60 | I25: 110 | J25: 51 | K25: 64990 | L25: 58040 | M25: =IF(L25=0,0,(K25-L25)/L25) -> 0.119745 | N25: =IF(G25<H25,"부족",IF(G25<H25*1.25,"주의","정상")) -> 부족 | O25: 36372 | P25: 20933 | Q25: 34905 | R25: =IF(J25=0,"",ROUND(G25/(J25/30),0)) -> 19 | S25: 2창고-B1 | T25: 46179 | U25: 안전재고 미만
A26: FS-PN-022 | B26: 기어 세트 | C26: 부자재 | D26: B형-32 | E26: SET | F26: 한빛전장 | G26: 115 | H26: 55 | I26: 133 | J26: 89 | K26: 12780 | L26: 12690 | M26: =IF(L26=0,0,(K26-L26)/L26) -> 0.0070921986 | N26: =IF(G26<H26,"부족",IF(G26<H26*1.25,"주의","정상")) -> 정상 | O26: 39729 | P26: 20394 | Q26: 28286 | R26: =IF(J26=0,"",ROUND(G26/(J26/30),0)) -> 39 | S26: 2창고-B3 | T26: 46187
A27: FS-MC-023 | B27: 와셔 세트 | C27: 부자재 | D27: 고내열-33 | E27: EA | F27: 대성정밀 | G27: 92 | H27: 39 | I27: 74 | J27: 59 | K27: 40170 | L27: 36500 | M27: =IF(L27=0,0,(K27-L27)/L27) -> 0.10054795 | N27: =IF(G27<H27,"부족",IF(G27<H27*1.25,"주의","정상")) -> 정상 | O27: 37443 | P27: 21372 | Q27: 26246 | R27: =IF(J27=0,"",ROUND(G27/(J27/30),0)) -> 47 | S27: 3창고-C2 | T27: 46195
A28: FS-EL-024 | B28: 접지선 | C28: 소모품 | D28: B형-34 | E28: M | F28: 베트남파트너스 | G28: 20 | H28: 22 | I28: 41 | J28: 15 | K28: 40220 | L28: 40530 | M28: =IF(L28=0,0,(K28-L28)/L28) -> -0.0076486553 | N28: =IF(G28<H28,"부족",IF(G28<H28*1.25,"주의","정상")) -> 부족 | O28: 30730 | P28: 25303 | Q28: 24618 | R28: =IF(J28=0,"",ROUND(G28/(J28/30),0)) -> 40 | S28: 외주창고-VN | T28: 46201 | U28: 안전재고 미만
A29: FS-RM-025 | B29: 메인 프레임 | C29: 포장재 | D29: 방수-35 | E29: ROLL | F29: 유니텍소재 | G29: 100 | H29: 56 | I29: 102 | J29: 89 | K29: 60330 | L29: 54930 | M29: =IF(L29=0,0,(K29-L29)/L29) -> 0.098306936 | N29: =IF(G29<H29,"부족",IF(G29<H29*1.25,"주의","정상")) -> 정상 | O29: 31860 | P29: 24240 | Q29: 22815 | R29: =IF(J29=0,"",ROUND(G29/(J29/30),0)) -> 34 | S29: 1창고-A1 | T29: 46168
A30: FS-EL-026 | B30: 고정 플레이트 | C30: 원자재 | D30: 고내열-36 | E30: ROLL | F30: 동양패키징 | G30: 61 | H30: 80 | I30: 191 | J30: 56 | K30: 84760 | L30: 83790 | M30: =IF(L30=0,0,(K30-L30)/L30) -> 0.01157656 | N30: =IF(G30<H30,"부족",IF(G30<H30*1.25,"주의","정상")) -> 부족 | O30: 35748 | P30: 24320 | Q30: 26956 | R30: =IF(J30=0,"",ROUND(G30/(J30/30),0)) -> 33 | S30: 1창고-A2 | T30: 46152 | U30: 안전재고 미만
A31: FS-EL-027 | B31: 커넥터 12핀 | C31: 부자재 | D31: 표준-37 | E31: M | F31: 세명산업 | G31: 42 | H31: 63 | I31: 142 | J31: 76 | K31: 53270 | L31: 49300 | M31: =IF(L31=0,0,(K31-L31)/L31) -> 0.080527383 | N31: =IF(G31<H31,"부족",IF(G31<H31*1.25,"주의","정상")) -> 부족 | O31: 37996 | P31: 21857 | Q31: 33402 | R31: =IF(J31=0,"",ROUND(G31/(J31/30),0)) -> 17 | S31: 2창고-B1 | T31: 46135 | U31: 안전재고 미만
A32: FS-EL-028 | B32: LCD 패널 | C32: 부자재 | D32: 고내열-38 | E32: M | F32: K-Parts | G32: 42 | H32: 42 | I32: 73 | J32: 65 | K32: 92610 | L32: 81700 | M32: =IF(L32=0,0,(K32-L32)/L32) -> 0.13353733 | N32: =IF(G32<H32,"부족",IF(G32<H32*1.25,"주의","정상")) -> 주의 | O32: 32188 | P32: 26954 | Q32: 28867 | R32: =IF(J32=0,"",ROUND(G32/(J32/30),0)) -> 19 | S32: 2창고-B3 | T32: 46175 | U32: 재고 소진 임박
A33: FS-PN-029 | B33: 방열판 | C33: 부자재 | D33: 고내열-39 | E33: ROLL | F33: 한빛전장 | G33: 25 | H33: 46 | I33: 88 | J33: 42 | K33: 50200 | L33: 50980 | M33: =IF(L33=0,0,(K33-L33)/L33) -> -0.015300118 | N33: =IF(G33<H33,"부족",IF(G33<H33*1.25,"주의","정상")) -> 부족 | O33: 34021 | P33: 27703 | Q33: 24095 | R33: =IF(J33=0,"",ROUND(G33/(J33/30),0)) -> 18 | S33: 3창고-C2 | T33: 46176 | U33: 안전재고 미만
A34: FS-EL-030 | B34: 퓨즈 홀더 | C34: 부자재 | D34: 표준-40 | E34: M | F34: 대성정밀 | G34: 23 | H34: 31 | I34: 58 | J34: 29 | K34: 46130 | L34: 41450 | M34: =IF(L34=0,0,(K34-L34)/L34) -> 0.11290712 | N34: =IF(G34<H34,"부족",IF(G34<H34*1.25,"주의","정상")) -> 부족 | O34: 38206 | P34: 22538 | Q34: 31280 | R34: =IF(J34=0,"",ROUND(G34/(J34/30),0)) -> 24 | S34: 외주창고-VN | T34: 46148 | U34: 안전재고 미만
A35: FS-RM-031 | B35: 스프링 핀 | C35: 소모품 | D35: 고내열-41 | E35: KG | F35: 베트남파트너스 | G35: 57 | H35: 76 | I35: 132 | J35: 100 | K35: 75360 | L35: 69870 | M35: =IF(L35=0,0,(K35-L35)/L35) -> 0.078574495 | N35: =IF(G35<H35,"부족",IF(G35<H35*1.25,"주의","정상")) -> 부족 | O35: 36211 | P35: 25934 | Q35: 29451 | R35: =IF(J35=0,"",ROUND(G35/(J35/30),0)) -> 17 | S35: 1창고-A1 | T35: 46145 | U35: 안전재고 미만
A36: FS-MC-032 | B36: 케이블 타이 | C36: 포장재 | D36: 방수-42 | E36: SET | F36: 유니텍소재 | G36: 66 | H36: 32 | I36: 68 | J36: 40 | K36: 77580 | L36: 67730 | M36: =IF(L36=0,0,(K36-L36)/L36) -> 0.14543039 | N36: =IF(G36<H36,"부족",IF(G36<H36*1.25,"주의","정상")) -> 정상 | O36: 30208 | P36: 27015 | Q36: 27498 | R36: =IF(J36=0,"",ROUND(G36/(J36/30),0)) -> 50 | S36: 1창고-A2 | T36: 46157
A37: FS-PK-033 | B37: 절연 테이프 | C37: 원자재 | D37: A형-43 | E37: M | F37: 동양패키징 | G37: 26 | H37: 83 | I37: 172 | J37: 87 | K37: 47100 | L37: 43300 | M37: =IF(L37=0,0,(K37-L37)/L37) -> 0.087759815 | N37: =IF(G37<H37,"부족",IF(G37<H37*1.25,"주의","정상")) -> 부족 | O37: 36023 | P37: 27558 | Q37: 24633 | R37: =IF(J37=0,"",ROUND(G37/(J37/30),0)) -> 9 | S37: 2창고-B1 | T37: 46134 | U37: 안전재고 미만
A38: FS-EL-034 | B38: 고무 풋 | C38: 부자재 | D38: A형-44 | E38: BOX | F38: 세명산업 | G38: 42 | H38: 49 | I38: 120 | J38: 71 | K38: 90500 | L38: 83250 | M38: =IF(L38=0,0,(K38-L38)/L38) -> 0.087087087 | N38: =IF(G38<H38,"부족",IF(G38<H38*1.25,"주의","정상")) -> 부족 | O38: 39444 | P38: 21944 | Q38: 24746 | R38: =IF(J38=0,"",ROUND(G38/(J38/30),0)) -> 18 | S38: 2창고-B3 | T38: 46147 | U38: 안전재고 미만
A39: FS-MC-035 | B39: 스테퍼 드라이버 | C39: 부자재 | D39: A형-45 | E39: M | F39: K-Parts | G39: 136 | H39: 60 | I39: 115 | J39: 69 | K39: 23750 | L39: 24230 | M39: =IF(L39=0,0,(K39-L39)/L39) -> -0.019810153 | N39: =IF(G39<H39,"부족",IF(G39<H39*1.25,"주의","정상")) -> 정상 | O39: 32109 | P39: 20924 | Q39: 34878 | R39: =IF(J39=0,"",ROUND(G39/(J39/30),0)) -> 59 | S39: 3창고-C2 | T39: 46171
A40: FS-PK-036 | B40: 토크 리미터 | C40: 부자재 | D40: A형-46 | E40: SET | F40: 한빛전장 | G40: 29 | H40: 48 | I40: 102 | J40: 49 | K40: 74040 | L40: 68770 | M40: =IF(L40=0,0,(K40-L40)/L40) -> 0.076632252 | N40: =IF(G40<H40,"부족",IF(G40<H40*1.25,"주의","정상")) -> 부족 | O40: 36163 | P40: 23519 | Q40: 30627 | R40: =IF(J40=0,"",ROUND(G40/(J40/30),0)) -> 18 | S40: 외주창고-VN | T40: 46197 | U40: 안전재고 미만
A41: FS-PN-037 | B41: 에어 피팅 | C41: 부자재 | D41: 방수-47 | E41: ROLL | F41: 대성정밀 | G41: 69 | H41: 29 | I41: 68 | J41: 30 | K41: 50200 | L41: 50330 | M41: =IF(L41=0,0,(K41-L41)/L41) -> -0.0025829525 | N41: =IF(G41<H41,"부족",IF(G41<H41*1.25,"주의","정상")) -> 정상 | O41: 32187 | P41: 28811 | Q41: 25448 | R41: =IF(J41=0,"",ROUND(G41/(J41/30),0)) -> 69 | S41: 1창고-A1 | T41: 46158
...

Sheet 대시보드_지표
A1: 재고 대시보드 계산 예시 | B1: 재고 대시보드 계산 예시 | C1: 재고 대시보드 계산 예시 | D1: 재고 대시보드 계산 예시 | E1: 재고 대시보드 계산 예시 | F1: 재고 대시보드 계산 예시 | G1: 재고 대시보드 계산 예시 | H1: 재고 대시보드 계산 예시
A3: 지표 | B3: 값 | D3: 활용 메모
A4: 전체 품목 수 | B4: =COUNTA(재고현황!A5:A44) -> 40 | D4: FactoryScribe 메인 화면에서 재고 잔여량, 부족 재고, 부품가격 상승률, 생산품 실거래량 같은 지표를 계산할 때 사용할 수 있는 더미 원본입니다. 실제 서비스에서는 이 파일을 파싱해 inventory_items 같은 구조화 테이블로 저장한 뒤 대시보드 값을 계산하는 방식이 안전합니다. | E4: FactoryScribe 메인 화면에서 재고 잔여량, 부족 재고, 부품가격 상승률, 생산품 실거래량 같은 지표를 계산할 때 사용할 수 있는 더미 원본입니다. 실제 서비스에서는 이 파일을 파싱해 inventory_items 같은 구조화 테이블로 저장한 뒤 대시보드 값을 계산하는 방식이 안전합니다. | F4: FactoryScribe 메인 화면에서 재고 잔여량, 부족 재고, 부품가격 상승률, 생산품 실거래량 같은 지표를 계산할 때 사용할 수 있는 더미 원본입니다. 실제 서비스에서는 이 파일을 파싱해 inventory_items 같은 구조화 테이블로 저장한 뒤 대시보드 값을 계산하는 방식이 안전합니다. | G4: FactoryScribe 메인 화면에서 재고 잔여량, 부족 재고, 부품가격 상승률, 생산품 실거래량 같은 지표를 계산할 때 사용할 수 있는 더미 원본입니다. 실제 서비스에서는 이 파일을 파싱해 inventory_items 같은 구조화 테이블로 저장한 뒤 대시보드 값을 계산하는 방식이 안전합니다. | H4: FactoryScribe 메인 화면에서 재고 잔여량, 부족 재고, 부품가격 상승률, 생산품 실거래량 같은 지표를 계산할 때 사용할 수 있는 더미 원본입니다. 실제 서비스에서는 이 파일을 파싱해 inventory_items 같은 구조화 테이블로 저장한 뒤 대시보드 값을 계산하는 방식이 안전합니다.
A5: 총 현재고 수량 | B5: =SUM(재고현황!G5:G44) -> 2548 | D5: FactoryScribe 메인 화면에서 재고 잔여량, 부족 재고, 부품가격 상승률, 생산품 실거래량 같은 지표를 계산할 때 사용할 수 있는 더미 원본입니다. 실제 서비스에서는 이 파일을 파싱해 inventory_items 같은 구조화 테이블로 저장한 뒤 대시보드 값을 계산하는 방식이 안전합니다. | E5: FactoryScribe 메인 화면에서 재고 잔여량, 부족 재고, 부품가격 상승률, 생산품 실거래량 같은 지표를 계산할 때 사용할 수 있는 더미 원본입니다. 실제 서비스에서는 이 파일을 파싱해 inventory_items 같은 구조화 테이블로 저장한 뒤 대시보드 값을 계산하는 방식이 안전합니다. | F5: FactoryScribe 메인 화면에서 재고 잔여량, 부족 재고, 부품가격 상승률, 생산품 실거래량 같은 지표를 계산할 때 사용할 수 있는 더미 원본입니다. 실제 서비스에서는 이 파일을 파싱해 inventory_items 같은 구조화 테이블로 저장한 뒤 대시보드 값을 계산하는 방식이 안전합니다. | G5: FactoryScribe 메인 화면에서 재고 잔여량, 부족 재고, 부품가격 상승률, 생산품 실거래량 같은 지표를 계산할 때 사용할 수 있는 더미 원본입니다. 실제 서비스에서는 이 파일을 파싱해 inventory_items 같은 구조화 테이블로 저장한 뒤 대시보드 값을 계산하는 방식이 안전합니다. | H5: FactoryScribe 메인 화면에서 재고 잔여량, 부족 재고, 부품가격 상승률, 생산품 실거래량 같은 지표를 계산할 때 사용할 수 있는 더미 원본입니다. 실제 서비스에서는 이 파일을 파싱해 inventory_items 같은 구조화 테이블로 저장한 뒤 대시보드 값을 계산하는 방식이 안전합니다.
A6: 부족 재고 품목 수 | B6: =COUNTIF(재고현황!N5:N44,"부족") -> 20 | D6: FactoryScribe 메인 화면에서 재고 잔여량, 부족 재고, 부품가격 상승률, 생산품 실거래량 같은 지표를 계산할 때 사용할 수 있는 더미 원본입니다. 실제 서비스에서는 이 파일을 파싱해 inventory_items 같은 구조화 테이블로 저장한 뒤 대시보드 값을 계산하는 방식이 안전합니다. | E6: FactoryScribe 메인 화면에서 재고 잔여량, 부족 재고, 부품가격 상승률, 생산품 실거래량 같은 지표를 계산할 때 사용할 수 있는 더미 원본입니다. 실제 서비스에서는 이 파일을 파싱해 inventory_items 같은 구조화 테이블로 저장한 뒤 대시보드 값을 계산하는 방식이 안전합니다. | F6: FactoryScribe 메인 화면에서 재고 잔여량, 부족 재고, 부품가격 상승률, 생산품 실거래량 같은 지표를 계산할 때 사용할 수 있는 더미 원본입니다. 실제 서비스에서는 이 파일을 파싱해 inventory_items 같은 구조화 테이블로 저장한 뒤 대시보드 값을 계산하는 방식이 안전합니다. | G6: FactoryScribe 메인 화면에서 재고 잔여량, 부족 재고, 부품가격 상승률, 생산품 실거래량 같은 지표를 계산할 때 사용할 수 있는 더미 원본입니다. 실제 서비스에서는 이 파일을 파싱해 inventory_items 같은 구조화 테이블로 저장한 뒤 대시보드 값을 계산하는 방식이 안전합니다. | H6: FactoryScribe 메인 화면에서 재고 잔여량, 부족 재고, 부품가격 상승률, 생산품 실거래량 같은 지표를 계산할 때 사용할 수 있는 더미 원본입니다. 실제 서비스에서는 이 파일을 파싱해 inventory_items 같은 구조화 테이블로 저장한 뒤 대시보드 값을 계산하는 방식이 안전합니다.
A7: 주의 재고 품목 수 | B7: =COUNTIF(재고현황!N5:N44,"주의") -> 2 | D7: FactoryScribe 메인 화면에서 재고 잔여량, 부족 재고, 부품가격 상승률, 생산품 실거래량 같은 지표를 계산할 때 사용할 수 있는 더미 원본입니다. 실제 서비스에서는 이 파일을 파싱해 inventory_items 같은 구조화 테이블로 저장한 뒤 대시보드 값을 계산하는 방식이 안전합니다. | E7: FactoryScribe 메인 화면에서 재고 잔여량, 부족 재고, 부품가격 상승률, 생산품 실거래량 같은 지표를 계산할 때 사용할 수 있는 더미 원본입니다. 실제 서비스에서는 이 파일을 파싱해 inventory_items 같은 구조화 테이블로 저장한 뒤 대시보드 값을 계산하는 방식이 안전합니다. | F7: FactoryScribe 메인 화면에서 재고 잔여량, 부족 재고, 부품가격 상승률, 생산품 실거래량 같은 지표를 계산할 때 사용할 수 있는 더미 원본입니다. 실제 서비스에서는 이 파일을 파싱해 inventory_items 같은 구조화 테이블로 저장한 뒤 대시보드 값을 계산하는 방식이 안전합니다. | G7: FactoryScribe 메인 화면에서 재고 잔여량, 부족 재고, 부품가격 상승률, 생산품 실거래량 같은 지표를 계산할 때 사용할 수 있는 더미 원본입니다. 실제 서비스에서는 이 파일을 파싱해 inventory_items 같은 구조화 테이블로 저장한 뒤 대시보드 값을 계산하는 방식이 안전합니다. | H7: FactoryScribe 메인 화면에서 재고 잔여량, 부족 재고, 부품가격 상승률, 생산품 실거래량 같은 지표를 계산할 때 사용할 수 있는 더미 원본입니다. 실제 서비스에서는 이 파일을 파싱해 inventory_items 같은 구조화 테이블로 저장한 뒤 대시보드 값을 계산하는 방식이 안전합니다.
A8: 평균 가격 상승률 | B8: =AVERAGE(재고현황!M5:M44) -> 0.060699846 | D8: FactoryScribe 메인 화면에서 재고 잔여량, 부족 재고, 부품가격 상승률, 생산품 실거래량 같은 지표를 계산할 때 사용할 수 있는 더미 원본입니다. 실제 서비스에서는 이 파일을 파싱해 inventory_items 같은 구조화 테이블로 저장한 뒤 대시보드 값을 계산하는 방식이 안전합니다. | E8: FactoryScribe 메인 화면에서 재고 잔여량, 부족 재고, 부품가격 상승률, 생산품 실거래량 같은 지표를 계산할 때 사용할 수 있는 더미 원본입니다. 실제 서비스에서는 이 파일을 파싱해 inventory_items 같은 구조화 테이블로 저장한 뒤 대시보드 값을 계산하는 방식이 안전합니다. | F8: FactoryScribe 메인 화면에서 재고 잔여량, 부족 재고, 부품가격 상승률, 생산품 실거래량 같은 지표를 계산할 때 사용할 수 있는 더미 원본입니다. 실제 서비스에서는 이 파일을 파싱해 inventory_items 같은 구조화 테이블로 저장한 뒤 대시보드 값을 계산하는 방식이 안전합니다. | G8: FactoryScribe 메인 화면에서 재고 잔여량, 부족 재고, 부품가격 상승률, 생산품 실거래량 같은 지표를 계산할 때 사용할 수 있는 더미 원본입니다. 실제 서비스에서는 이 파일을 파싱해 inventory_items 같은 구조화 테이블로 저장한 뒤 대시보드 값을 계산하는 방식이 안전합니다. | H8: FactoryScribe 메인 화면에서 재고 잔여량, 부족 재고, 부품가격 상승률, 생산품 실거래량 같은 지표를 계산할 때 사용할 수 있는 더미 원본입니다. 실제 서비스에서는 이 파일을 파싱해 inventory_items 같은 구조화 테이블로 저장한 뒤 대시보드 값을 계산하는 방식이 안전합니다.
A9: 10% 이상 상승 품목 수 | B9: =COUNTIF(재고현황!M5:M44,">=0.1") -> 13
